<?xml version="1.0" encoding="utf-8"?>
<!-- This URDF was automatically created by SolidWorks to URDF Exporter! Originally created by Stephen Brawner (brawner@gmail.com) 
     Commit Version: 1.6.0-4-g7f85cfe  Build Version: 1.6.7995.38578
     For more information, please see http://wiki.ros.org/sw_urdf_exporter -->
<robot
  name="rArm">
  <link name="world"/>
  <joint name="world_to_base" type="fixed">
     <origin xyz="0 0 0" rpy="0 0 0"/>
     <parent link="world"/>
     <child link="base_link"/>
  </joint>
  <link
    name="base_link">
    <inertial>
      <origin
        xyz="-0.000243959622646744 0.0543589402237403 0.000140309878435986"
        rpy="0 0 0" />
      <mass
        value="0.429647225640808" />
      <inertia
        ixx="0.00138239181405175"
        ixy="6.97781156848522E-06"
        ixz="-1.47068009017832E-08"
        iyy="0.000822037201604634"
        iyz="3.4874101377122E-06"
        izz="0.00138158698467479" />
    </inertial>
    <visual>
      <origin
        xyz="0 0 0"
        rpy="0 0 0" />
      <geometry>
        <mesh
          filename="package://rArm/meshes/base_link.STL" />
      </geometry>
      <material
        name="">
        <color
          rgba="0.823529411764706 0.823529411764706 0.823529411764706 1" />
      </material>
    </visual>
    <collision>
      <origin
        xyz="0 0 0"
        rpy="0 0 0" />
      <geometry>
        <mesh
          filename="package://rArm/meshes/base_link.STL" />
      </geometry>
    </collision>
  </link>
  <link
    name="link_1">
    <inertial>
      <origin
        xyz="0.0240701175699888 0.0359232664993875 9.99507819035298E-05"
        rpy="0 0 0" />
      <mass
        value="0.0595250686049314" />
      <inertia
        ixx="2.56584148800544E-05"
        ixy="-1.09986135806387E-05"
        ixz="-1.17035223619903E-07"
        iyy="3.87637926630439E-05"
        iyz="3.39922467094331E-08"
        izz="3.69407209069928E-05" />
    </inertial>
    <visual>
      <origin
        xyz="0 0 0"
        rpy="0 0 0" />
      <geometry>
        <mesh
          filename="package://rArm/meshes/link_1.STL" />
      </geometry>
      <material
        name="">
        <color
          rgba="0.792156862745098 0.819607843137255 0.933333333333333 1" />
      </material>
    </visual>
    <collision>
      <origin
        xyz="0 0 0"
        rpy="0 0 0" />
      <geometry>
        <mesh
          filename="package://rArm/meshes/link_1.STL" />
      </geometry>
    </collision>
  </link>
  <joint
    name="joint_1"
    type="revolute">
    <origin
      xyz="0 0 0.1076"
      rpy="1.5708 0 0.0099134" />
    <parent
      link="base_link" />
    <child
      link="link_1" />
    <axis
      xyz="0 1 0" />
    <limit
      lower="-1.57"
      upper="1.57"
      effort="300"
      velocity="3" />
  </joint>
  <link
    name="link_2">
    <inertial>
      <origin
        xyz="-5.77584369427213E-05 -9.95517525412271E-05 0.0199158403290279"
        rpy="0 0 0" />
      <mass
        value="0.421675621337573" />
      <inertia
        ixx="0.00110476472353023"
        ixy="-5.84051901309569E-07"
        ixz="1.69794505556865E-07"
        iyy="0.000137814016788281"
        iyz="1.05134879133715E-07"
        izz="0.00110070555722074" />
    </inertial>
    <visual>
      <origin
        xyz="0 0.1 0"
        rpy="0 0 0" />
      <geometry>
        <mesh
          filename="package://rArm/meshes/link_2.STL" />
      </geometry>
      <material
        name="">
        <color
          rgba="0.792156862745098 0.819607843137255 0.933333333333333 1" />
      </material>
    </visual>
    <collision>
      <origin
        xyz="0 0.1 0"
        rpy="0 0 0" />
      <geometry>
        <mesh
          filename="package://rArm/meshes/link_2.STL" />
      </geometry>
    </collision>
  </link>
  <joint
    name="joint_2"
    type="revolute">
    <origin
      xyz="-0.0295 0.0535 0"
      rpy="-0.47834 1.5708 -0.47839" />
    <parent
      link="link_1" />
    <child
      link="link_2" />
    <axis
      xyz="0 0 1" />
    <limit
      lower="0"
      upper="1.57"
      effort="200"
      velocity="3" />
  </joint>
  <link
    name="link_3">
    <inertial>
      <origin
        xyz="0.0376139394572023 -0.0475378250287087 0.0409355826997525"
        rpy="0 0 0" />
      <mass
        value="0.161594463227238" />
      <inertia
        ixx="0.000133417271587139"
        ixy="-4.04852847949907E-05"
        ixz="1.57601761028247E-05"
        iyy="7.62005896975345E-05"
        iyz="2.78428759677757E-05"
        izz="0.000131383815910836" />
    </inertial>
    <visual>
      <origin
        xyz="0 0 0"
        rpy="0 0 0" />
      <geometry>
        <mesh
          filename="package://rArm/meshes/link_3.STL" />
      </geometry>
      <material
        name="">
        <color
          rgba="0.792156862745098 0.819607843137255 0.933333333333333 1" />
      </material>
    </visual>
    <collision>
      <origin
        xyz="0 0 0"
        rpy="0 0 0" />
      <geometry>
        <mesh
          filename="package://rArm/meshes/link_3.STL" />
      </geometry>
    </collision>
  </link>
  <joint
    name="joint_3"
    type="revolute">
    <origin
      xyz="0 0.2 0.0033574"
      rpy="-0.1 -1.5708 0" />
    <parent
      link="link_2" />
    <child
      link="link_3" />
    <axis
      xyz="-1 0 0" />
    <limit
      lower="0"
      upper="3.142"
      effort="200"
      velocity="3" />
  </joint>
  <link
    name="link_4">
    <inertial>
      <origin
        xyz="-0.00575300999128266 -0.043700495134287 0.00015612234623974"
        rpy="0 0 0" />
      <mass
        value="0.162848333889868" />
      <inertia
        ixx="0.000111122629024118"
        ixy="-4.36000343519648E-07"
        ixz="-1.60976703876801E-07"
        iyy="4.35604794263214E-05"
        iyz="-1.18106248974113E-07"
        izz="0.000105520267846187" />
    </inertial>
    <visual>
      <origin
        xyz="0 0 0"
        rpy="0 0 0" />
      <geometry>
        <mesh
          filename="package://rArm/meshes/link_4.STL" />
      </geometry>
      <material
        name="">
        <color
          rgba="0.792156862745098 0.819607843137255 0.933333333333333 1" />
      </material>
    </visual>
    <collision>
      <origin
        xyz="0 0 0"
        rpy="0 0 0" />
      <geometry>
        <mesh
          filename="package://rArm/meshes/link_4.STL" />
      </geometry>
    </collision>
  </link>
  <joint
    name="joint_4"
    type="revolute">
    <origin
      xyz="0.026143 -0.109 0.047631"
      rpy="0 0 0" />
    <parent
      link="link_3" />
    <child
      link="link_4" />
    <axis
      xyz="0 1 0" />
    <limit
      lower="0"
      upper="3.142"
      effort="200"
      velocity="3" />
  </joint>
  <link
    name="link_5">
    <inertial>
      <origin
        xyz="-0.0316306190248438 0.000226147263476556 0.0664198247447715"
        rpy="0 0 0" />
      <mass
        value="0.155236127458214" />
      <inertia
        ixx="0.000130984067592516"
        ixy="-8.04956263237243E-08"
        ixz="4.12217342807323E-05"
        iyy="0.000144738658809021"
        iyz="1.93716079942043E-07"
        izz="5.51248372533013E-05" />
    </inertial>
    <visual>
      <origin
        xyz="0 0 0"
        rpy="0 0 0" />
      <geometry>
        <mesh
          filename="package://rArm/meshes/link_5.STL" />
      </geometry>
      <material
        name="">
        <color
          rgba="0.792156862745098 0.819607843137255 0.933333333333333 1" />
      </material>
    </visual>
    <collision>
      <origin
        xyz="0 0 0"
        rpy="0 0 0" />
      <geometry>
        <mesh
          filename="package://rArm/meshes/link_5.STL" />
      </geometry>
    </collision>
  </link>
  <joint
    name="joint_5"
    type="revolute">
    <origin
      xyz="0.0415 -0.0735 0"
      rpy="0.05154 0 0" />
    <parent
      link="link_4" />
    <child
      link="link_5" />
    <axis
      xyz="1 0 0" />
    <limit
      lower="0"
      upper="3.142"
      effort="200"
      velocity="3" />
  </joint>
  <link
    name="link_6">
    <inertial>
      <origin
        xyz="-0.1 -0.1 0"
        rpy="0 0 0" />
      <mass
        value="0.00881635142307731" />
      <inertia
        ixx="6.52932081295388E-07"
        ixy="-5.41981015806961E-23"
        ixz="1.50133281178375E-22"
        iyy="6.52932081295387E-07"
        iyz="5.49661517041487E-22"
        izz="9.30679454720125E-07" />
    </inertial>
    <visual>
      <origin
        xyz="0.00486 0.0032 0"
        rpy="0 0 0" />
      <geometry>
        <mesh
          filename="package://rArm/meshes/link_6.STL" />
      </geometry>
      <material
        name="">
        <color
          rgba="1 1 1 1" />
      </material>
    </visual>
    <collision>
      <origin
        xyz="0.00468 0.00242 0"
        rpy="0 0 0" />
      <geometry>
        <mesh
          filename="package://rArm/meshes/link_6.STL" />
      </geometry>
    </collision>
  </link>
  <joint
    name="joint_6"
    type="revolute">
    <origin
      xyz="-0.0365 0 0.11241"
      rpy="3.1416 0 -2.6181" />
    <parent
      link="link_5" />
    <child
      link="link_6" />
    <axis
      xyz="0 0 1" />
    <limit
      lower="0"
      upper="3.142"
      effort="200"
      velocity="3" />
  </joint>
</robot>
